<robot name="tst">
  <link name="base_link"/>
  <joint name ="base_linkToCR(77)" type="fixed">
    <parent link="base_link"/>
    <child link="CR(77)"/>
    <origin xyz="0 0 0" rpy="0 0 0"/>
  </joint>

  <!-- Rear body_roll_joint -->
  <link name="CR(1)">
    <!-- Only visual, No collision -->
    <visual>
      <geometry>
        <cylinder length="0.01" radius="0.03"/>
      </geometry>
      <origin xyz="0 0 0" rpy="0 1.5708 0"/>
      <material name="black">
        <color rgba="0.0 0.0 0.0 2.0"/>
      </material>
    </visual>
  </link>

  <!-- body -->
  <joint name="body_roll_joint(1)" type="revolute">
    <parent link="CR(1)"/>
    <child link="body_roll_joint_cap(1)"/>
    <origin xyz="-0.05 0 0" rpy="0 0 0"/>
    <axis xyz="0 0 1"/>
    <limit lower="-1.5708" upper="1.5708" effort="0" velocity="0"/>
  </joint>
  <link name="body_roll_joint_cap(1)">
    <visual>
      <geometry>
        <cylinder length="0.1" radius="0.05"/>
      </geometry>
      <origin xyz="0 0 0" rpy="0 0 0"/>
      <material name="body_roll_joint_color">
        <color rgba="0.0 1.0 0.5 2.0"/>
      </material>
    </visual>
  </link>

  <!-- Front body_roll_joint -->
  <joint name="body_roll_joint_link_BD2CF(1)" type="fixed">
    <parent link="body_roll_joint_cap(1)"/>
    <child link="CF(1)"/>
    <origin xyz="-0.05 0 0" rpy="0 0 3.14159"/>
  </joint>
  <link name="CF(1)">
    <!-- Only visual, No collision -->
    <visual>
      <geometry>
        <cylinder length="0.01" radius="0.03"/>
      </geometry>
      <origin xyz="0 0 0" rpy="0 1.5708 0"/>
      <material name="black">
        <color rgba="0.0 0.0 0.0 2.0"/>
      </material>
    </visual>
  </link>

  <!-- Rear connector -->
  <link name="CR(4)">
    <!-- Only visual, No collision -->
    <visual>
      <geometry>
        <cylinder length="0.01" radius="0.03"/>
      </geometry>
      <origin xyz="0 0 0" rpy="0 1.5708 0"/>
      <material name="black">
        <color rgba="0.0 0.0 0.0 2.0"/>
      </material>
    </visual>
  </link>

  <!-- body -->
  <joint name="CR2BD(4)" type="fixed">
    <parent link="CR(4)"/>
    <child link="limb_link15cm_body(4)"/>
    <origin xyz="0 0 0" rpy="0 0 0"/>
  </joint>
  <link name="limb_link15cm_body(4)">
    <visual>
      <geometry>
        <cylinder length="0.15" radius="0.03"/>
      </geometry>
      <origin xyz="-0.075 0 0" rpy="0 1.5708 0"/>
      <material name="limb_link_15cm_color">
        <color rgba="0.0 0.5 1.0 2.0"/>
      </material>
    </visual>
  </link>

  <!-- Front connector -->
  <joint name="limb_link15cm_BD2CF(4)" type="fixed">
    <parent link="limb_link15cm_body(4)"/>
    <child link="CF(4)"/>
    <origin xyz="-0.15 0 0" rpy="0 0 3.14159"/>
  </joint>
  <link name="CF(4)">
    <!-- Only visual, No collision -->
    <visual>
      <geometry>
        <cylinder length="0.01" radius="0.03"/>
      </geometry>
      <origin xyz="0 0 0" rpy="0 1.5708 0"/>
      <material name="black">
        <color rgba="0.0 0.0 0.0 2.0"/>
      </material>
    </visual>
  </link>

  <!-- Rear connector -->
  <link name="CR(10)">
    <!-- Only visual, No collision -->
    <visual>
      <geometry>
        <cylinder length="0.01" radius="0.03"/>
      </geometry>
      <origin xyz="0 0 0" rpy="0 1.5708 0"/>
      <material name="black">
        <color rgba="0.0 0.0 0.0 2.0"/>
      </material>
    </visual>
  </link>

  <!-- body -->
  <joint name="CR2BD(10)" type="fixed">
    <parent link="CR(10)"/>
    <child link="limb_link15cm_body(10)"/>
    <origin xyz="0 0 0" rpy="0 0 0"/>
  </joint>
  <link name="limb_link15cm_body(10)">
    <visual>
      <geometry>
        <cylinder length="0.15" radius="0.03"/>
      </geometry>
      <origin xyz="-0.075 0 0" rpy="0 1.5708 0"/>
      <material name="limb_link_15cm_color">
        <color rgba="0.0 0.5 1.0 2.0"/>
      </material>
    </visual>
  </link>

  <!-- Front connector -->
  <joint name="limb_link15cm_BD2CF(10)" type="fixed">
    <parent link="limb_link15cm_body(10)"/>
    <child link="CF(10)"/>
    <origin xyz="-0.15 0 0" rpy="0 0 3.14159"/>
  </joint>
  <link name="CF(10)">
    <!-- Only visual, No collision -->
    <visual>
      <geometry>
        <cylinder length="0.01" radius="0.03"/>
      </geometry>
      <origin xyz="0 0 0" rpy="0 1.5708 0"/>
      <material name="black">
        <color rgba="0.0 0.0 0.0 2.0"/>
      </material>
    </visual>
  </link>

  <!-- Rear connector -->
  <link name="CR(13)">
    <!-- Only visual, No collision -->
    <visual>
      <geometry>
        <cylinder length="0.01" radius="0.03"/>
      </geometry>
      <origin xyz="0 0 0" rpy="0 1.5708 0"/>
      <material name="black">
        <color rgba="0.0 0.0 0.0 2.0"/>
      </material>
    </visual>
  </link>

  <!-- body -->
  <joint name="CR2BD(13)" type="fixed">
    <parent link="CR(13)"/>
    <child link="limb_link15cm_body(13)"/>
    <origin xyz="0 0 0" rpy="0 0 0"/>
  </joint>
  <link name="limb_link15cm_body(13)">
    <visual>
      <geometry>
        <cylinder length="0.15" radius="0.03"/>
      </geometry>
      <origin xyz="-0.075 0 0" rpy="0 1.5708 0"/>
      <material name="limb_link_15cm_color">
        <color rgba="0.0 0.5 1.0 2.0"/>
      </material>
    </visual>
  </link>

  <!-- Front connector -->
  <joint name="limb_link15cm_BD2CF(13)" type="fixed">
    <parent link="limb_link15cm_body(13)"/>
    <child link="CF(13)"/>
    <origin xyz="-0.15 0 0" rpy="0 0 3.14159"/>
  </joint>
  <link name="CF(13)">
    <!-- Only visual, No collision -->
    <visual>
      <geometry>
        <cylinder length="0.01" radius="0.03"/>
      </geometry>
      <origin xyz="0 0 0" rpy="0 1.5708 0"/>
      <material name="black">
        <color rgba="0.0 0.0 0.0 2.0"/>
      </material>
    </visual>
  </link>

  <!-- Rear limb_rigid_joint -->
  <link name="CR(16)">
    <!-- Only visual, No collision -->
    <visual>
      <geometry>
        <cylinder length="0.01" radius="0.03"/>
      </geometry>
      <origin xyz="0 0 0" rpy="0 1.5708 0"/>
      <material name="black">
        <color rgba="0.0 0.0 0.0 2.0"/>
      </material>
    </visual>
  </link>

  <!-- limb -->
  <joint name="CR2BD(16)" type="fixed">
    <parent link="CR(16)"/>
    <child link="limb_rigid_joint_cap(16)"/>
    <origin xyz="0 0 0" rpy="0 0 0"/>
  </joint>
  <link name="limb_rigid_joint_cap(16)">
    <visual>
      <geometry>
        <box size="0.06 0.06 0.06"/>
      </geometry>
      <origin xyz="-0.03 0 0" rpy="0 0 0"/>
      <material name="limb_rigid_joint_color">
        <color rgba="2.0 1.0 0.5 2.0"/>
      </material>
    </visual>
  </link>

  <!-- Front limb_rigid_joint -->
  <joint name="limb_rigid_joint_link_BD2CF(16)" type="fixed">
    <parent link="limb_rigid_joint_cap(16)"/>
    <child link="CF(16)"/>
    <origin xyz="-0.06 0 0" rpy="0 0 3.14159"/>
  </joint>
  <link name="CF(16)">
    <!-- Only visual, No collision -->
    <visual>
      <geometry>
        <cylinder length="0.01" radius="0.03"/>
      </geometry>
      <origin xyz="0 0 0" rpy="0 1.5708 0"/>
      <material name="black">
        <color rgba="0.0 0.0 0.0 2.0"/>
      </material>
    </visual>
  </link>

  <!-- Rear connector -->
  <link name="CR(22)">
    <!-- Only visual, No collision -->
    <visual>
      <geometry>
        <cylinder length="0.01" radius="0.03"/>
      </geometry>
      <origin xyz="0 0 0" rpy="0 1.5708 0"/>
      <material name="black">
        <color rgba="0.0 0.0 0.0 2.0"/>
      </material>
    </visual>
  </link>

  <!-- body -->
  <joint name="CR2BD(22)" type="fixed">
    <parent link="CR(22)"/>
    <child link="body_link_body(22)"/>
    <origin xyz="0 0 0" rpy="0 0 0"/>
  </joint>
  <link name="body_link_body(22)">
    <visual>
      <geometry>
        <cylinder length="0.30" radius="0.05"/>
      </geometry>
      <origin xyz="-0.15 0 0" rpy="0 1.5708 0"/>
      <material name="body_link_color">
        <color rgba="0.5 0.5 1.0 2.0"/>
      </material>
    </visual>
  </link>

  <!-- Front connector -->
  <joint name="body_link_BD2CF(22)" type="fixed">
    <parent link="body_link_body(22)"/>
    <child link="CF(22)"/>
    <origin xyz="-0.30 0 0" rpy="0 0 3.14159"/>
  </joint>
  <link name="CF(22)">
    <!-- Only visual, No collision -->
    <visual>
      <geometry>
        <cylinder length="0.01" radius="0.03"/>
      </geometry>
      <origin xyz="0 0 0" rpy="0 1.5708 0"/>
      <material name="black">
        <color rgba="0.0 0.0 0.0 2.0"/>
      </material>
    </visual>
  </link>

  <!-- Right side connector -->
  <joint name="body_link_BD2CRi(22)" type="fixed">
    <parent link="body_link_body(22)"/>
    <child link="CRi(22)"/>
    <origin xyz="-0.15 0.05 0" rpy="0 0 1.5708"/>
  </joint>
  <link name="CRi(22)">
    <!-- Only visual, No collision -->
    <visual>
      <geometry>
        <cylinder length="0.01" radius="0.03"/>
      </geometry>
      <origin xyz="0 0 0" rpy="0 1.5708 0"/>
      <material name="black">
        <color rgba="0.0 0.0 0.0 2.0"/>
      </material>
    </visual>
  </link>

  <!-- Left side connector -->
  <joint name="body_link_BD2CL(22)" type="fixed">
    <parent link="body_link_body(22)"/>
    <child link="CL(22)"/>
    <origin xyz="-0.15 -0.05 0" rpy="0 0 -1.5708"/>
  </joint>
  <link name="CL(22)">
    <!-- Only visual, No collision -->
    <visual>
      <geometry>
        <cylinder length="0.01" radius="0.03"/>
      </geometry>
      <origin xyz="0 0 0" rpy="0 1.5708 0"/>
      <material name="black">
        <color rgba="0.0 0.0 0.0 2.0"/>
      </material>
    </visual>
  </link>

  <!-- Rear connector -->
  <link name="CR(27)">
    <!-- Only visual, No collision -->
    <visual>
      <geometry>
        <cylinder length="0.01" radius="0.03"/>
      </geometry>
      <origin xyz="0 0 0" rpy="0 1.5708 0"/>
      <material name="black">
        <color rgba="0.0 0.0 0.0 2.0"/>
      </material>
    </visual>
  </link>

  <!-- Front connector -->
  <joint name="CR2CF(27)" type="fixed">
    <parent link="CR(27)"/>
    <child link="CF(27)"/>
    <origin xyz="-0.01 0 0" rpy="0 0 3.14159"/>
  </joint>
  <link name="CF(27)">
    <!-- Only visual, No collision -->
    <visual>
      <geometry>
        <cylinder length="0.01" radius="0.03"/>
      </geometry>
      <origin xyz="0 0 0" rpy="0 1.5708 0"/>
      <material name="black">
        <color rgba="0.0 0.0 0.0 2.0"/>
      </material>
    </visual>
  </link>

  <!-- Rear connector -->
  <link name="CR(30)">
    <!-- Only visual, No collision -->
    <visual>
      <geometry>
        <cylinder length="0.01" radius="0.03"/>
      </geometry>
      <origin xyz="0 0 0" rpy="0 1.5708 0"/>
      <material name="black">
        <color rgba="0.0 0.0 0.0 2.0"/>
      </material>
    </visual>
  </link>

  <!-- body -->
  <joint name="CR2BD(30)" type="fixed">
    <parent link="CR(30)"/>
    <child link="mount_link_body(30)"/>
    <origin xyz="0 0 0" rpy="0 0 0"/>
  </joint>
  <link name="mount_link_body(30)">
    <visual>
      <geometry>
        <cylinder length="0.10" radius="0.03"/>
      </geometry>
      <origin xyz="-0.05 0 0" rpy="0 1.5708 0"/>
      <material name="mount_link_color">
        <color rgba="0.0 0.5 1.0 2.0"/>
      </material>
    </visual>
  </link>

  <!-- Front connector -->
  <joint name="mount_link_BD2CF(30)" type="fixed">
    <parent link="mount_link_body(30)"/>
    <child link="CF(30)"/>
    <origin xyz="-0.1 0 0" rpy="0 0 3.14159"/>
  </joint>
  <link name="CF(30)">
    <!-- Only visual, No collision -->
    <visual>
      <geometry>
        <cylinder length="0.01" radius="0.03"/>
      </geometry>
      <origin xyz="0 0 0" rpy="0 1.5708 0"/>
      <material name="black">
        <color rgba="0.0 0.0 0.0 2.0"/>
      </material>
    </visual>
  </link>

  <!-- Rear connector -->
  <link name="CR(33)">
    <!-- Only visual, No collision -->
    <visual>
      <geometry>
        <cylinder length="0.01" radius="0.03"/>
      </geometry>
      <origin xyz="0 0 0" rpy="0 1.5708 0"/>
      <material name="black">
        <color rgba="0.0 0.0 0.0 2.0"/>
      </material>
    </visual>
  </link>

  <!-- Front connector -->
  <joint name="CR2CF(33)" type="fixed">
    <parent link="CR(33)"/>
    <child link="CF(33)"/>
    <origin xyz="-0.01 0 0" rpy="0 0 3.14159"/>
  </joint>
  <link name="CF(33)">
    <!-- Only visual, No collision -->
    <visual>
      <geometry>
        <cylinder length="0.01" radius="0.03"/>
      </geometry>
      <origin xyz="0 0 0" rpy="0 1.5708 0"/>
      <material name="black">
        <color rgba="0.0 0.0 0.0 2.0"/>
      </material>
    </visual>
  </link>

  <!-- Rear connector -->
  <link name="CR(61)">
    <!-- Only visual, No collision -->
    <visual>
      <geometry>
        <cylinder length="0.01" radius="0.03"/>
      </geometry>
      <origin xyz="0 0 0" rpy="0 1.5708 0"/>
      <material name="black">
        <color rgba="0.0 0.0 0.0 2.0"/>
      </material>
    </visual>
  </link>

  <!-- body -->
  <joint name="CR2BD(61)" type="fixed">
    <parent link="CR(61)"/>
    <child link="mount_link_body(61)"/>
    <origin xyz="0 0 0" rpy="0 0 0"/>
  </joint>
  <link name="mount_link_body(61)">
    <visual>
      <geometry>
        <cylinder length="0.10" radius="0.03"/>
      </geometry>
      <origin xyz="-0.05 0 0" rpy="0 1.5708 0"/>
      <material name="mount_link_color">
        <color rgba="0.0 0.5 1.0 2.0"/>
      </material>
    </visual>
  </link>

  <!-- Front connector -->
  <joint name="mount_link_BD2CF(61)" type="fixed">
    <parent link="mount_link_body(61)"/>
    <child link="CF(61)"/>
    <origin xyz="-0.1 0 0" rpy="0 0 3.14159"/>
  </joint>
  <link name="CF(61)">
    <!-- Only visual, No collision -->
    <visual>
      <geometry>
        <cylinder length="0.01" radius="0.03"/>
      </geometry>
      <origin xyz="0 0 0" rpy="0 1.5708 0"/>
      <material name="black">
        <color rgba="0.0 0.0 0.0 2.0"/>
      </material>
    </visual>
  </link>

  <!-- Rear limb_knee_joint -->
  <link name="CR(65)">
    <!-- Only visual, No collision -->
    <visual>
      <geometry>
        <cylinder length="0.01" radius="0.03"/>
      </geometry>
      <origin xyz="0 0 0" rpy="0 1.5708 0"/>
      <material name="black">
        <color rgba="0.0 0.0 0.0 2.0"/>
      </material>
    </visual>
  </link>

  <!-- limb -->
  <joint name="limb_knee_joint_i(65)" type="revolute">
    <parent link="CR(65)"/>
    <child link="limb_knee_joint_cap(65)"/>
    <origin xyz="-0.03 0 0" rpy="0 0 0"/>
    <axis xyz="1 0 0"/>
    <limit lower="-1.5708" upper="1.5708" effort="0" velocity="0"/>
  </joint>
  <link name="limb_knee_joint_cap(65)">
    <visual>
      <geometry>
        <cylinder length="0.06" radius="0.03"/>
      </geometry>
      <origin xyz="0 0 0" rpy="0 0 0"/>
      <material name="limb_knee_joint_color">
        <color rgba="0.0 1.0 0.5 2.0"/>
      </material>
    </visual>
  </link>

  <!-- middle -->
  <joint name="limb_knee_joint_r(65)" type="revolute">
    <parent link="limb_knee_joint_cap(65)"/>
    <child link="limb_knee_joint_invisible_link(65)"/>
    <origin xyz="0 0 0" rpy="0 0 0"/>
    <axis xyz="0 0 1"/>
    <limit lower="-1.5708" upper="1.5708" effort="0" velocity="0"/>
  </joint>
  <link name="limb_knee_joint_invisible_link(65)">
  </link>

  <!-- Front limb_knee_joint -->
  <joint name="limb_knee_joint_invisible(65)" type="fixed">
    <parent link="limb_knee_joint_invisible_link(65)"/>
    <child link="CF(65)"/>
    <origin xyz="-0.03 0 0" rpy="0 0 3.14159"/>
  </joint>
  <link name="CF(65)">
    <!-- Only visual, No collision -->
    <visual>
      <geometry>
        <cylinder length="0.01" radius="0.03"/>
      </geometry>
      <origin xyz="0.0 0 0" rpy="0 1.5708 0"/>
      <material name="black">
        <color rgba="0.0 0.0 0.0 2.0"/>
      </material>
    </visual>
  </link>

  <!-- Rear limb_knee_joint -->
  <link name="CR(68)">
    <!-- Only visual, No collision -->
    <visual>
      <geometry>
        <cylinder length="0.01" radius="0.03"/>
      </geometry>
      <origin xyz="0 0 0" rpy="0 1.5708 0"/>
      <material name="black">
        <color rgba="0.0 0.0 0.0 2.0"/>
      </material>
    </visual>
  </link>

  <!-- limb -->
  <joint name="limb_knee_joint_i(68)" type="revolute">
    <parent link="CR(68)"/>
    <child link="limb_knee_joint_cap(68)"/>
    <origin xyz="-0.03 0 0" rpy="0 0 0"/>
    <axis xyz="1 0 0"/>
    <limit lower="-1.5708" upper="1.5708" effort="0" velocity="0"/>
  </joint>
  <link name="limb_knee_joint_cap(68)">
    <visual>
      <geometry>
        <cylinder length="0.06" radius="0.03"/>
      </geometry>
      <origin xyz="0 0 0" rpy="0 0 0"/>
      <material name="limb_knee_joint_color">
        <color rgba="0.0 1.0 0.5 2.0"/>
      </material>
    </visual>
  </link>

  <!-- middle -->
  <joint name="limb_knee_joint_r(68)" type="revolute">
    <parent link="limb_knee_joint_cap(68)"/>
    <child link="limb_knee_joint_invisible_link(68)"/>
    <origin xyz="0 0 0" rpy="0 0 0"/>
    <axis xyz="0 0 1"/>
    <limit lower="-1.5708" upper="1.5708" effort="0" velocity="0"/>
  </joint>
  <link name="limb_knee_joint_invisible_link(68)">
  </link>

  <!-- Front limb_knee_joint -->
  <joint name="limb_knee_joint_invisible(68)" type="fixed">
    <parent link="limb_knee_joint_invisible_link(68)"/>
    <child link="CF(68)"/>
    <origin xyz="-0.03 0 0" rpy="0 0 3.14159"/>
  </joint>
  <link name="CF(68)">
    <!-- Only visual, No collision -->
    <visual>
      <geometry>
        <cylinder length="0.01" radius="0.03"/>
      </geometry>
      <origin xyz="0.0 0 0" rpy="0 1.5708 0"/>
      <material name="black">
        <color rgba="0.0 0.0 0.0 2.0"/>
      </material>
    </visual>
  </link>

  <!-- Rear connector -->
  <link name="CR(71)">
    <!-- Only visual, No collision -->
    <visual>
      <geometry>
        <cylinder length="0.01" radius="0.03"/>
      </geometry>
      <origin xyz="0 0 0" rpy="0 1.5708 0"/>
      <material name="black">
        <color rgba="0.0 0.0 0.0 2.0"/>
      </material>
    </visual>
  </link>

  <!-- Front connector -->
  <joint name="CR2CF(71)" type="fixed">
    <parent link="CR(71)"/>
    <child link="CF(71)"/>
    <origin xyz="-0.01 0 0" rpy="0 0 3.14159"/>
  </joint>
  <link name="CF(71)">
    <!-- Only visual, No collision -->
    <visual>
      <geometry>
        <cylinder length="0.01" radius="0.03"/>
      </geometry>
      <origin xyz="0 0 0" rpy="0 1.5708 0"/>
      <material name="black">
        <color rgba="0.0 0.0 0.0 2.0"/>
      </material>
    </visual>
  </link>

  <!-- Rear connector -->
  <link name="CR(74)">
    <!-- Only visual, No collision -->
    <visual>
      <geometry>
        <cylinder length="0.01" radius="0.03"/>
      </geometry>
      <origin xyz="0 0 0" rpy="0 1.5708 0"/>
      <material name="black">
        <color rgba="0.0 0.0 0.0 2.0"/>
      </material>
    </visual>
  </link>

  <!-- body -->
  <joint name="CR2BD(74)" type="fixed">
    <parent link="CR(74)"/>
    <child link="mount_link_body(74)"/>
    <origin xyz="0 0 0" rpy="0 0 0"/>
  </joint>
  <link name="mount_link_body(74)">
    <visual>
      <geometry>
        <cylinder length="0.10" radius="0.03"/>
      </geometry>
      <origin xyz="-0.05 0 0" rpy="0 1.5708 0"/>
      <material name="mount_link_color">
        <color rgba="0.0 0.5 1.0 2.0"/>
      </material>
    </visual>
  </link>

  <!-- Front connector -->
  <joint name="mount_link_BD2CF(74)" type="fixed">
    <parent link="mount_link_body(74)"/>
    <child link="CF(74)"/>
    <origin xyz="-0.1 0 0" rpy="0 0 3.14159"/>
  </joint>
  <link name="CF(74)">
    <!-- Only visual, No collision -->
    <visual>
      <geometry>
        <cylinder length="0.01" radius="0.03"/>
      </geometry>
      <origin xyz="0 0 0" rpy="0 1.5708 0"/>
      <material name="black">
        <color rgba="0.0 0.0 0.0 2.0"/>
      </material>
    </visual>
  </link>

  <!-- Rear connector -->
  <link name="CR(77)">
    <!-- Only visual, No collision -->
    <visual>
      <geometry>
        <cylinder length="0.01" radius="0.03"/>
      </geometry>
      <origin xyz="0 0 0" rpy="0 1.5708 0"/>
      <material name="black">
        <color rgba="0.0 0.0 0.0 2.0"/>
      </material>
    </visual>
  </link>

  <!-- Front connector -->
  <joint name="CR2CF(77)" type="fixed">
    <parent link="CR(77)"/>
    <child link="CF(77)"/>
    <origin xyz="-0.01 0 0" rpy="0 0 3.14159"/>
  </joint>
  <link name="CF(77)">
    <!-- Only visual, No collision -->
    <visual>
      <geometry>
        <cylinder length="0.01" radius="0.03"/>
      </geometry>
      <origin xyz="0 0 0" rpy="0 1.5708 0"/>
      <material name="black">
        <color rgba="0.0 0.0 0.0 2.0"/>
      </material>
    </visual>
  </link>

  <!-- Rear connector -->
  <link name="CR(80)">
    <!-- Only visual, No collision -->
    <visual>
      <geometry>
        <cylinder length="0.01" radius="0.03"/>
      </geometry>
      <origin xyz="0 0 0" rpy="0 1.5708 0"/>
      <material name="black">
        <color rgba="0.0 0.0 0.0 2.0"/>
      </material>
    </visual>
  </link>

  <!-- body -->
  <joint name="CR2BD(80)" type="fixed">
    <parent link="CR(80)"/>
    <child link="mount_link_body(80)"/>
    <origin xyz="0 0 0" rpy="0 0 0"/>
  </joint>
  <link name="mount_link_body(80)">
    <visual>
      <geometry>
        <cylinder length="0.10" radius="0.03"/>
      </geometry>
      <origin xyz="-0.05 0 0" rpy="0 1.5708 0"/>
      <material name="mount_link_color">
        <color rgba="0.0 0.5 1.0 2.0"/>
      </material>
    </visual>
  </link>

  <!-- Front connector -->
  <joint name="mount_link_BD2CF(80)" type="fixed">
    <parent link="mount_link_body(80)"/>
    <child link="CF(80)"/>
    <origin xyz="-0.1 0 0" rpy="0 0 3.14159"/>
  </joint>
  <link name="CF(80)">
    <!-- Only visual, No collision -->
    <visual>
      <geometry>
        <cylinder length="0.01" radius="0.03"/>
      </geometry>
      <origin xyz="0 0 0" rpy="0 1.5708 0"/>
      <material name="black">
        <color rgba="0.0 0.0 0.0 2.0"/>
      </material>
    </visual>
  </link>

  <!-- Rear connector -->
  <link name="CR(85)">
    <!-- Only visual, No collision -->
    <visual>
      <geometry>
        <cylinder length="0.01" radius="0.03"/>
      </geometry>
      <origin xyz="0 0 0" rpy="0 1.5708 0"/>
      <material name="black">
        <color rgba="0.0 0.0 0.0 2.0"/>
      </material>
    </visual>
  </link>

  <!-- body -->
  <joint name="CR2BD(85)" type="fixed">
    <parent link="CR(85)"/>
    <child link="body_link_body(85)"/>
    <origin xyz="0 0 0" rpy="0 0 0"/>
  </joint>
  <link name="body_link_body(85)">
    <visual>
      <geometry>
        <cylinder length="0.30" radius="0.05"/>
      </geometry>
      <origin xyz="-0.15 0 0" rpy="0 1.5708 0"/>
      <material name="body_link_color">
        <color rgba="0.5 0.5 1.0 2.0"/>
      </material>
    </visual>
  </link>

  <!-- Front connector -->
  <joint name="body_link_BD2CF(85)" type="fixed">
    <parent link="body_link_body(85)"/>
    <child link="CF(85)"/>
    <origin xyz="-0.30 0 0" rpy="0 0 3.14159"/>
  </joint>
  <link name="CF(85)">
    <!-- Only visual, No collision -->
    <visual>
      <geometry>
        <cylinder length="0.01" radius="0.03"/>
      </geometry>
      <origin xyz="0 0 0" rpy="0 1.5708 0"/>
      <material name="black">
        <color rgba="0.0 0.0 0.0 2.0"/>
      </material>
    </visual>
  </link>

  <!-- Right side connector -->
  <joint name="body_link_BD2CRi(85)" type="fixed">
    <parent link="body_link_body(85)"/>
    <child link="CRi(85)"/>
    <origin xyz="-0.15 0.05 0" rpy="0 0 1.5708"/>
  </joint>
  <link name="CRi(85)">
    <!-- Only visual, No collision -->
    <visual>
      <geometry>
        <cylinder length="0.01" radius="0.03"/>
      </geometry>
      <origin xyz="0 0 0" rpy="0 1.5708 0"/>
      <material name="black">
        <color rgba="0.0 0.0 0.0 2.0"/>
      </material>
    </visual>
  </link>

  <!-- Left side connector -->
  <joint name="body_link_BD2CL(85)" type="fixed">
    <parent link="body_link_body(85)"/>
    <child link="CL(85)"/>
    <origin xyz="-0.15 -0.05 0" rpy="0 0 -1.5708"/>
  </joint>
  <link name="CL(85)">
    <!-- Only visual, No collision -->
    <visual>
      <geometry>
        <cylinder length="0.01" radius="0.03"/>
      </geometry>
      <origin xyz="0 0 0" rpy="0 1.5708 0"/>
      <material name="black">
        <color rgba="0.0 0.0 0.0 2.0"/>
      </material>
    </visual>
  </link>

  <!-- Rear connector -->
  <link name="CR(90)">
    <!-- Only visual, No collision -->
    <visual>
      <geometry>
        <cylinder length="0.01" radius="0.03"/>
      </geometry>
      <origin xyz="0 0 0" rpy="0 1.5708 0"/>
      <material name="black">
        <color rgba="0.0 0.0 0.0 2.0"/>
      </material>
    </visual>
  </link>

  <!-- Front connector -->
  <joint name="CR2CF(90)" type="fixed">
    <parent link="CR(90)"/>
    <child link="CF(90)"/>
    <origin xyz="-0.01 0 0" rpy="0 0 3.14159"/>
  </joint>
  <link name="CF(90)">
    <!-- Only visual, No collision -->
    <visual>
      <geometry>
        <cylinder length="0.01" radius="0.03"/>
      </geometry>
      <origin xyz="0 0 0" rpy="0 1.5708 0"/>
      <material name="black">
        <color rgba="0.0 0.0 0.0 2.0"/>
      </material>
    </visual>
  </link>

  <!-- Rear connector -->
  <link name="CR(93)">
    <!-- Only visual, No collision -->
    <visual>
      <geometry>
        <cylinder length="0.01" radius="0.03"/>
      </geometry>
      <origin xyz="0 0 0" rpy="0 1.5708 0"/>
      <material name="black">
        <color rgba="0.0 0.0 0.0 2.0"/>
      </material>
    </visual>
  </link>

  <!-- body -->
  <joint name="CR2BD(93)" type="fixed">
    <parent link="CR(93)"/>
    <child link="mount_link_body(93)"/>
    <origin xyz="0 0 0" rpy="0 0 0"/>
  </joint>
  <link name="mount_link_body(93)">
    <visual>
      <geometry>
        <cylinder length="0.10" radius="0.03"/>
      </geometry>
      <origin xyz="-0.05 0 0" rpy="0 1.5708 0"/>
      <material name="mount_link_color">
        <color rgba="0.0 0.5 1.0 2.0"/>
      </material>
    </visual>
  </link>

  <!-- Front connector -->
  <joint name="mount_link_BD2CF(93)" type="fixed">
    <parent link="mount_link_body(93)"/>
    <child link="CF(93)"/>
    <origin xyz="-0.1 0 0" rpy="0 0 3.14159"/>
  </joint>
  <link name="CF(93)">
    <!-- Only visual, No collision -->
    <visual>
      <geometry>
        <cylinder length="0.01" radius="0.03"/>
      </geometry>
      <origin xyz="0 0 0" rpy="0 1.5708 0"/>
      <material name="black">
        <color rgba="0.0 0.0 0.0 2.0"/>
      </material>
    </visual>
  </link>

  <!-- Rear connector -->
  <link name="CR(96)">
    <!-- Only visual, No collision -->
    <visual>
      <geometry>
        <cylinder length="0.01" radius="0.03"/>
      </geometry>
      <origin xyz="0 0 0" rpy="0 1.5708 0"/>
      <material name="black">
        <color rgba="0.0 0.0 0.0 2.0"/>
      </material>
    </visual>
  </link>

  <!-- Front connector -->
  <joint name="CR2CF(96)" type="fixed">
    <parent link="CR(96)"/>
    <child link="CF(96)"/>
    <origin xyz="-0.01 0 0" rpy="0 0 3.14159"/>
  </joint>
  <link name="CF(96)">
    <!-- Only visual, No collision -->
    <visual>
      <geometry>
        <cylinder length="0.01" radius="0.03"/>
      </geometry>
      <origin xyz="0 0 0" rpy="0 1.5708 0"/>
      <material name="black">
        <color rgba="0.0 0.0 0.0 2.0"/>
      </material>
    </visual>
  </link>

  <!-- Rear connector -->
  <link name="CR(99)">
    <!-- Only visual, No collision -->
    <visual>
      <geometry>
        <cylinder length="0.01" radius="0.03"/>
      </geometry>
      <origin xyz="0 0 0" rpy="0 1.5708 0"/>
      <material name="black">
        <color rgba="0.0 0.0 0.0 2.0"/>
      </material>
    </visual>
  </link>

  <!-- body -->
  <joint name="CR2BD(99)" type="fixed">
    <parent link="CR(99)"/>
    <child link="mount_link_body(99)"/>
    <origin xyz="0 0 0" rpy="0 0 0"/>
  </joint>
  <link name="mount_link_body(99)">
    <visual>
      <geometry>
        <cylinder length="0.10" radius="0.03"/>
      </geometry>
      <origin xyz="-0.05 0 0" rpy="0 1.5708 0"/>
      <material name="mount_link_color">
        <color rgba="0.0 0.5 1.0 2.0"/>
      </material>
    </visual>
  </link>

  <!-- Front connector -->
  <joint name="mount_link_BD2CF(99)" type="fixed">
    <parent link="mount_link_body(99)"/>
    <child link="CF(99)"/>
    <origin xyz="-0.1 0 0" rpy="0 0 3.14159"/>
  </joint>
  <link name="CF(99)">
    <!-- Only visual, No collision -->
    <visual>
      <geometry>
        <cylinder length="0.01" radius="0.03"/>
      </geometry>
      <origin xyz="0 0 0" rpy="0 1.5708 0"/>
      <material name="black">
        <color rgba="0.0 0.0 0.0 2.0"/>
      </material>
    </visual>
  </link>

  <!-- Rear wheel -->
  <link name="CR(102)">
    <!-- Only visual, No collision -->
    <visual>
      <geometry>
        <cylinder length="0.01" radius="0.03"/>
      </geometry>
      <origin xyz="0 0 0" rpy="0 1.5708 0"/>
      <material name="black">
        <color rgba="0.0 0.0 0.0 2.0"/>
      </material>
    </visual>
  </link>

  <!-- limb -->
  <joint name="wheel(102)" type="continuous">
    <parent link="CR(102)"/>
    <child link="wheel_tyre(102)"/>
    <origin xyz="-0.03 0 0" rpy="0 0 0"/>
    <axis xyz="1 0 0"/>
  </joint>
  <link name="wheel_tyre(102)">
    <visual>
      <geometry>
        <cylinder length="0.06" radius="0.1"/>
      </geometry>
      <origin xyz="0 0 0" rpy="0 1.5708 0"/>
      <material name="wheel_color">
        <color rgba="0.0 0.5 1.0 2.0"/>
      </material>
    </visual>
  </link>

  <!-- Rear empty_edge -->
  <link name="CR(104)">
    <!-- Only visual, No collision -->
    <visual>
      <geometry>
        <cylinder length="0.01" radius="0.03"/>
      </geometry>
      <origin xyz="0 0 0" rpy="0 1.5708 0"/>
      <material name="black">
        <color rgba="0.0 0.0 0.0 2.0"/>
      </material>
    </visual>
  </link>

  <!-- limb -->
  <joint name="empty_edge(104)" type="fixed">
    <parent link="CR(104)"/>
    <child link="empty_edge_ball(104)"/>
    <origin xyz="0 0 0" rpy="0 0 0"/>
  </joint>
  <link name="empty_edge_ball(104)">
    <visual>
      <geometry>
        <sphere radius="0.03"/>
      </geometry>
      <origin xyz="0 0 0" rpy="0 1.5708 0"/>
      <material name="empty_edge_color">
        <color rgba="0.0 0.5 1.0 2.0"/>
      </material>
    </visual>
  </link>

  <!-- Rear wheel -->
  <link name="CR(110)">
    <!-- Only visual, No collision -->
    <visual>
      <geometry>
        <cylinder length="0.01" radius="0.03"/>
      </geometry>
      <origin xyz="0 0 0" rpy="0 1.5708 0"/>
      <material name="black">
        <color rgba="0.0 0.0 0.0 2.0"/>
      </material>
    </visual>
  </link>

  <!-- limb -->
  <joint name="wheel(110)" type="continuous">
    <parent link="CR(110)"/>
    <child link="wheel_tyre(110)"/>
    <origin xyz="-0.03 0 0" rpy="0 0 0"/>
    <axis xyz="1 0 0"/>
  </joint>
  <link name="wheel_tyre(110)">
    <visual>
      <geometry>
        <cylinder length="0.06" radius="0.1"/>
      </geometry>
      <origin xyz="0 0 0" rpy="0 1.5708 0"/>
      <material name="wheel_color">
        <color rgba="0.0 0.5 1.0 2.0"/>
      </material>
    </visual>
  </link>

  <!-- Rear wheel -->
  <link name="CR(113)">
    <!-- Only visual, No collision -->
    <visual>
      <geometry>
        <cylinder length="0.01" radius="0.03"/>
      </geometry>
      <origin xyz="0 0 0" rpy="0 1.5708 0"/>
      <material name="black">
        <color rgba="0.0 0.0 0.0 2.0"/>
      </material>
    </visual>
  </link>

  <!-- limb -->
  <joint name="wheel(113)" type="continuous">
    <parent link="CR(113)"/>
    <child link="wheel_tyre(113)"/>
    <origin xyz="-0.03 0 0" rpy="0 0 0"/>
    <axis xyz="1 0 0"/>
  </joint>
  <link name="wheel_tyre(113)">
    <visual>
      <geometry>
        <cylinder length="0.06" radius="0.1"/>
      </geometry>
      <origin xyz="0 0 0" rpy="0 1.5708 0"/>
      <material name="wheel_color">
        <color rgba="0.0 0.5 1.0 2.0"/>
      </material>
    </visual>
  </link>

  <!-- Rear limb_knee_joint -->
  <link name="CR(116)">
    <!-- Only visual, No collision -->
    <visual>
      <geometry>
        <cylinder length="0.01" radius="0.03"/>
      </geometry>
      <origin xyz="0 0 0" rpy="0 1.5708 0"/>
      <material name="black">
        <color rgba="0.0 0.0 0.0 2.0"/>
      </material>
    </visual>
  </link>

  <!-- limb -->
  <joint name="limb_knee_joint_i(116)" type="revolute">
    <parent link="CR(116)"/>
    <child link="limb_knee_joint_cap(116)"/>
    <origin xyz="-0.03 0 0" rpy="0 0 0"/>
    <axis xyz="1 0 0"/>
    <limit lower="-1.5708" upper="1.5708" effort="0" velocity="0"/>
  </joint>
  <link name="limb_knee_joint_cap(116)">
    <visual>
      <geometry>
        <cylinder length="0.06" radius="0.03"/>
      </geometry>
      <origin xyz="0 0 0" rpy="0 0 0"/>
      <material name="limb_knee_joint_color">
        <color rgba="0.0 1.0 0.5 2.0"/>
      </material>
    </visual>
  </link>

  <!-- middle -->
  <joint name="limb_knee_joint_r(116)" type="revolute">
    <parent link="limb_knee_joint_cap(116)"/>
    <child link="limb_knee_joint_invisible_link(116)"/>
    <origin xyz="0 0 0" rpy="0 0 0"/>
    <axis xyz="0 0 1"/>
    <limit lower="-1.5708" upper="1.5708" effort="0" velocity="0"/>
  </joint>
  <link name="limb_knee_joint_invisible_link(116)">
  </link>

  <!-- Front limb_knee_joint -->
  <joint name="limb_knee_joint_invisible(116)" type="fixed">
    <parent link="limb_knee_joint_invisible_link(116)"/>
    <child link="CF(116)"/>
    <origin xyz="-0.03 0 0" rpy="0 0 3.14159"/>
  </joint>
  <link name="CF(116)">
    <!-- Only visual, No collision -->
    <visual>
      <geometry>
        <cylinder length="0.01" radius="0.03"/>
      </geometry>
      <origin xyz="0.0 0 0" rpy="0 1.5708 0"/>
      <material name="black">
        <color rgba="0.0 0.0 0.0 2.0"/>
      </material>
    </visual>
  </link>

  <!-- Rear limb_knee_joint -->
  <link name="CR(120)">
    <!-- Only visual, No collision -->
    <visual>
      <geometry>
        <cylinder length="0.01" radius="0.03"/>
      </geometry>
      <origin xyz="0 0 0" rpy="0 1.5708 0"/>
      <material name="black">
        <color rgba="0.0 0.0 0.0 2.0"/>
      </material>
    </visual>
  </link>

  <!-- limb -->
  <joint name="limb_knee_joint_i(120)" type="revolute">
    <parent link="CR(120)"/>
    <child link="limb_knee_joint_cap(120)"/>
    <origin xyz="-0.03 0 0" rpy="0 0 0"/>
    <axis xyz="1 0 0"/>
    <limit lower="-1.5708" upper="1.5708" effort="0" velocity="0"/>
  </joint>
  <link name="limb_knee_joint_cap(120)">
    <visual>
      <geometry>
        <cylinder length="0.06" radius="0.03"/>
      </geometry>
      <origin xyz="0 0 0" rpy="0 0 0"/>
      <material name="limb_knee_joint_color">
        <color rgba="0.0 1.0 0.5 2.0"/>
      </material>
    </visual>
  </link>

  <!-- middle -->
  <joint name="limb_knee_joint_r(120)" type="revolute">
    <parent link="limb_knee_joint_cap(120)"/>
    <child link="limb_knee_joint_invisible_link(120)"/>
    <origin xyz="0 0 0" rpy="0 0 0"/>
    <axis xyz="0 0 1"/>
    <limit lower="-1.5708" upper="1.5708" effort="0" velocity="0"/>
  </joint>
  <link name="limb_knee_joint_invisible_link(120)">
  </link>

  <!-- Front limb_knee_joint -->
  <joint name="limb_knee_joint_invisible(120)" type="fixed">
    <parent link="limb_knee_joint_invisible_link(120)"/>
    <child link="CF(120)"/>
    <origin xyz="-0.03 0 0" rpy="0 0 3.14159"/>
  </joint>
  <link name="CF(120)">
    <!-- Only visual, No collision -->
    <visual>
      <geometry>
        <cylinder length="0.01" radius="0.03"/>
      </geometry>
      <origin xyz="0.0 0 0" rpy="0 1.5708 0"/>
      <material name="black">
        <color rgba="0.0 0.0 0.0 2.0"/>
      </material>
    </visual>
  </link>

  <!-- Rear connector -->
  <link name="CR(125)">
    <!-- Only visual, No collision -->
    <visual>
      <geometry>
        <cylinder length="0.01" radius="0.03"/>
      </geometry>
      <origin xyz="0 0 0" rpy="0 1.5708 0"/>
      <material name="black">
        <color rgba="0.0 0.0 0.0 2.0"/>
      </material>
    </visual>
  </link>

  <!-- body -->
  <joint name="CR2BD(125)" type="fixed">
    <parent link="CR(125)"/>
    <child link="limb_link15cm_body(125)"/>
    <origin xyz="0 0 0" rpy="0 0 0"/>
  </joint>
  <link name="limb_link15cm_body(125)">
    <visual>
      <geometry>
        <cylinder length="0.15" radius="0.03"/>
      </geometry>
      <origin xyz="-0.075 0 0" rpy="0 1.5708 0"/>
      <material name="limb_link_15cm_color">
        <color rgba="0.0 0.5 1.0 2.0"/>
      </material>
    </visual>
  </link>

  <!-- Front connector -->
  <joint name="limb_link15cm_BD2CF(125)" type="fixed">
    <parent link="limb_link15cm_body(125)"/>
    <child link="CF(125)"/>
    <origin xyz="-0.15 0 0" rpy="0 0 3.14159"/>
  </joint>
  <link name="CF(125)">
    <!-- Only visual, No collision -->
    <visual>
      <geometry>
        <cylinder length="0.01" radius="0.03"/>
      </geometry>
      <origin xyz="0 0 0" rpy="0 1.5708 0"/>
      <material name="black">
        <color rgba="0.0 0.0 0.0 2.0"/>
      </material>
    </visual>
  </link>

  <!-- Rear connector -->
  <link name="CR(129)">
    <!-- Only visual, No collision -->
    <visual>
      <geometry>
        <cylinder length="0.01" radius="0.03"/>
      </geometry>
      <origin xyz="0 0 0" rpy="0 1.5708 0"/>
      <material name="black">
        <color rgba="0.0 0.0 0.0 2.0"/>
      </material>
    </visual>
  </link>

  <!-- body -->
  <joint name="CR2BD(129)" type="fixed">
    <parent link="CR(129)"/>
    <child link="limb_link15cm_body(129)"/>
    <origin xyz="0 0 0" rpy="0 0 0"/>
  </joint>
  <link name="limb_link15cm_body(129)">
    <visual>
      <geometry>
        <cylinder length="0.15" radius="0.03"/>
      </geometry>
      <origin xyz="-0.075 0 0" rpy="0 1.5708 0"/>
      <material name="limb_link_15cm_color">
        <color rgba="0.0 0.5 1.0 2.0"/>
      </material>
    </visual>
  </link>

  <!-- Front connector -->
  <joint name="limb_link15cm_BD2CF(129)" type="fixed">
    <parent link="limb_link15cm_body(129)"/>
    <child link="CF(129)"/>
    <origin xyz="-0.15 0 0" rpy="0 0 3.14159"/>
  </joint>
  <link name="CF(129)">
    <!-- Only visual, No collision -->
    <visual>
      <geometry>
        <cylinder length="0.01" radius="0.03"/>
      </geometry>
      <origin xyz="0 0 0" rpy="0 1.5708 0"/>
      <material name="black">
        <color rgba="0.0 0.0 0.0 2.0"/>
      </material>
    </visual>
  </link>

  <!-- Rear empty_edge -->
  <link name="CR(134)">
    <!-- Only visual, No collision -->
    <visual>
      <geometry>
        <cylinder length="0.01" radius="0.03"/>
      </geometry>
      <origin xyz="0 0 0" rpy="0 1.5708 0"/>
      <material name="black">
        <color rgba="0.0 0.0 0.0 2.0"/>
      </material>
    </visual>
  </link>

  <!-- limb -->
  <joint name="empty_edge(134)" type="fixed">
    <parent link="CR(134)"/>
    <child link="empty_edge_ball(134)"/>
    <origin xyz="0 0 0" rpy="0 0 0"/>
  </joint>
  <link name="empty_edge_ball(134)">
    <visual>
      <geometry>
        <sphere radius="0.03"/>
      </geometry>
      <origin xyz="0 0 0" rpy="0 1.5708 0"/>
      <material name="empty_edge_color">
        <color rgba="0.0 0.5 1.0 2.0"/>
      </material>
    </visual>
  </link>

  <!-- Rear empty_edge -->
  <link name="CR(137)">
    <!-- Only visual, No collision -->
    <visual>
      <geometry>
        <cylinder length="0.01" radius="0.03"/>
      </geometry>
      <origin xyz="0 0 0" rpy="0 1.5708 0"/>
      <material name="black">
        <color rgba="0.0 0.0 0.0 2.0"/>
      </material>
    </visual>
  </link>

  <!-- limb -->
  <joint name="empty_edge(137)" type="fixed">
    <parent link="CR(137)"/>
    <child link="empty_edge_ball(137)"/>
    <origin xyz="0 0 0" rpy="0 0 0"/>
  </joint>
  <link name="empty_edge_ball(137)">
    <visual>
      <geometry>
        <sphere radius="0.03"/>
      </geometry>
      <origin xyz="0 0 0" rpy="0 1.5708 0"/>
      <material name="empty_edge_color">
        <color rgba="0.0 0.5 1.0 2.0"/>
      </material>
    </visual>
  </link>
  <joint name ="CF(1)ToCR(85)" type="fixed">
    <parent link="CF(1)"/>
    <child link="CR(85)"/>
    <origin xyz="0 0 0" rpy="0 0 3.14159265359"/>
  </joint>
  <joint name ="CF(4)ToCR(16)" type="fixed">
    <parent link="CF(4)"/>
    <child link="CR(16)"/>
    <origin xyz="0 0 0" rpy="0 0 3.14159265359"/>
  </joint>
  <joint name ="CF(10)ToCR(102)" type="fixed">
    <parent link="CF(10)"/>
    <child link="CR(102)"/>
    <origin xyz="0 0 0" rpy="0 0 3.14159265359"/>
  </joint>
  <joint name ="CF(13)ToCR(104)" type="fixed">
    <parent link="CF(13)"/>
    <child link="CR(104)"/>
    <origin xyz="0 0 0" rpy="0 0 3.14159265359"/>
  </joint>
  <joint name ="CF(16)ToCR(13)" type="fixed">
    <parent link="CF(16)"/>
    <child link="CR(13)"/>
    <origin xyz="0 0 0" rpy="0 0 3.14159265359"/>
  </joint>
  <joint name ="CF(22)ToCR(1)" type="fixed">
    <parent link="CF(22)"/>
    <child link="CR(1)"/>
    <origin xyz="0 0 0" rpy="0 0 3.14159265359"/>
  </joint>
  <joint name ="CRi(22)ToCR(33)" type="fixed">
    <parent link="CRi(22)"/>
    <child link="CR(33)"/>
    <origin xyz="0 0 0" rpy="0 0 3.14159265359"/>
  </joint>
  <joint name ="CL(22)ToCR(27)" type="fixed">
    <parent link="CL(22)"/>
    <child link="CR(27)"/>
    <origin xyz="0 0 0" rpy="0 0 3.14159265359"/>
  </joint>
  <joint name ="CF(27)ToCR(30)" type="fixed">
    <parent link="CF(27)"/>
    <child link="CR(30)"/>
    <origin xyz="0 0 0" rpy="0 0 3.14159265359"/>
  </joint>
  <joint name ="CF(30)ToCR(116)" type="fixed">
    <parent link="CF(30)"/>
    <child link="CR(116)"/>
    <origin xyz="0 0 0" rpy="0 0 3.14159265359"/>
  </joint>
  <joint name ="CF(33)ToCR(61)" type="fixed">
    <parent link="CF(33)"/>
    <child link="CR(61)"/>
    <origin xyz="0 0 0" rpy="0 0 3.14159265359"/>
  </joint>
  <joint name ="CF(61)ToCR(120)" type="fixed">
    <parent link="CF(61)"/>
    <child link="CR(120)"/>
    <origin xyz="0 0 0" rpy="0 0 3.14159265359"/>
  </joint>
  <joint name ="CF(65)ToCR(10)" type="fixed">
    <parent link="CF(65)"/>
    <child link="CR(10)"/>
    <origin xyz="0 0 0" rpy="0 0 3.14159265359"/>
  </joint>
  <joint name ="CF(68)ToCR(4)" type="fixed">
    <parent link="CF(68)"/>
    <child link="CR(4)"/>
    <origin xyz="0 0 0" rpy="0 0 3.14159265359"/>
  </joint>
  <joint name ="CF(71)ToCR(74)" type="fixed">
    <parent link="CF(71)"/>
    <child link="CR(74)"/>
    <origin xyz="0 0 0" rpy="0 0 3.14159265359"/>
  </joint>
  <joint name ="CF(74)ToCR(68)" type="fixed">
    <parent link="CF(74)"/>
    <child link="CR(68)"/>
    <origin xyz="0 0 0" rpy="0 0 3.14159265359"/>
  </joint>
  <joint name ="CF(77)ToCR(80)" type="fixed">
    <parent link="CF(77)"/>
    <child link="CR(80)"/>
    <origin xyz="0 0 0" rpy="0 0 3.14159265359"/>
  </joint>
  <joint name ="CR(77)ToCR(22)" type="fixed">
    <parent link="CR(77)"/>
    <child link="CR(22)"/>
    <origin xyz="0 0 0" rpy="0 0 3.14159265359"/>
  </joint>
  <joint name ="CF(80)ToCR(65)" type="fixed">
    <parent link="CF(80)"/>
    <child link="CR(65)"/>
    <origin xyz="0 0 0" rpy="0 0 3.14159265359"/>
  </joint>
  <joint name ="CF(85)ToCR(71)" type="fixed">
    <parent link="CF(85)"/>
    <child link="CR(71)"/>
    <origin xyz="0 0 0" rpy="0 0 3.14159265359"/>
  </joint>
  <joint name ="CRi(85)ToCR(96)" type="fixed">
    <parent link="CRi(85)"/>
    <child link="CR(96)"/>
    <origin xyz="0 0 0" rpy="0 0 3.14159265359"/>
  </joint>
  <joint name ="CL(85)ToCR(90)" type="fixed">
    <parent link="CL(85)"/>
    <child link="CR(90)"/>
    <origin xyz="0 0 0" rpy="0 0 3.14159265359"/>
  </joint>
  <joint name ="CF(90)ToCR(93)" type="fixed">
    <parent link="CF(90)"/>
    <child link="CR(93)"/>
    <origin xyz="0 0 0" rpy="0 0 3.14159265359"/>
  </joint>
  <joint name ="CF(93)ToCR(110)" type="fixed">
    <parent link="CF(93)"/>
    <child link="CR(110)"/>
    <origin xyz="0 0 0" rpy="0 0 3.14159265359"/>
  </joint>
  <joint name ="CF(96)ToCR(99)" type="fixed">
    <parent link="CF(96)"/>
    <child link="CR(99)"/>
    <origin xyz="0 0 0" rpy="0 0 3.14159265359"/>
  </joint>
  <joint name ="CF(99)ToCR(113)" type="fixed">
    <parent link="CF(99)"/>
    <child link="CR(113)"/>
    <origin xyz="0 0 0" rpy="0 0 3.14159265359"/>
  </joint>
  <joint name ="CF(116)ToCR(125)" type="fixed">
    <parent link="CF(116)"/>
    <child link="CR(125)"/>
    <origin xyz="0 0 0" rpy="0 0 3.14159265359"/>
  </joint>
  <joint name ="CF(120)ToCR(129)" type="fixed">
    <parent link="CF(120)"/>
    <child link="CR(129)"/>
    <origin xyz="0 0 0" rpy="0 0 3.14159265359"/>
  </joint>
  <joint name ="CF(125)ToCR(134)" type="fixed">
    <parent link="CF(125)"/>
    <child link="CR(134)"/>
    <origin xyz="0 0 0" rpy="0 0 3.14159265359"/>
  </joint>
  <joint name ="CF(129)ToCR(137)" type="fixed">
    <parent link="CF(129)"/>
    <child link="CR(137)"/>
    <origin xyz="0 0 0" rpy="0 0 3.14159265359"/>
  </joint>
</robot>