<robot name="tst">
  <link name="base_link"/>
  <joint name ="base_linkToCR(57)" type="fixed">
    <parent link="base_link"/>
    <child link="CR(57)"/>
    <origin xyz="0 0 0" rpy="0 0 0"/>
  </joint>

  <!-- Rear connector -->
  <link name="CR(0)">
    <!-- Only visual, No collision -->
    <visual>
      <geometry>
        <cylinder length="0.01" radius="0.03"/>
      </geometry>
      <origin xyz="0 0 0" rpy="0 1.5708 0"/>
      <material name="black">
        <color rgba="0.0 0.0 0.0 2.0"/>
      </material>
    </visual>
  </link>

  <!-- body -->
  <joint name="CR2BD(0)" type="fixed">
    <parent link="CR(0)"/>
    <child link="body_link_body(0)"/>
    <origin xyz="0 0 0" rpy="0 0 0"/>
  </joint>
  <link name="body_link_body(0)">
    <visual>
      <geometry>
        <cylinder length="0.30" radius="0.05"/>
      </geometry>
      <origin xyz="-0.15 0 0" rpy="0 1.5708 0"/>
      <material name="body_link_color">
        <color rgba="0.5 0.5 1.0 2.0"/>
      </material>
    </visual>
  </link>

  <!-- Front connector -->
  <joint name="body_link_BD2CF(0)" type="fixed">
    <parent link="body_link_body(0)"/>
    <child link="CF(0)"/>
    <origin xyz="-0.30 0 0" rpy="0 0 3.14159"/>
  </joint>
  <link name="CF(0)">
    <!-- Only visual, No collision -->
    <visual>
      <geometry>
        <cylinder length="0.01" radius="0.03"/>
      </geometry>
      <origin xyz="0 0 0" rpy="0 1.5708 0"/>
      <material name="black">
        <color rgba="0.0 0.0 0.0 2.0"/>
      </material>
    </visual>
  </link>

  <!-- Right side connector -->
  <joint name="body_link_BD2CRi(0)" type="fixed">
    <parent link="body_link_body(0)"/>
    <child link="CRi(0)"/>
    <origin xyz="-0.15 0.05 0" rpy="0 0 1.5708"/>
  </joint>
  <link name="CRi(0)">
    <!-- Only visual, No collision -->
    <visual>
      <geometry>
        <cylinder length="0.01" radius="0.03"/>
      </geometry>
      <origin xyz="0 0 0" rpy="0 1.5708 0"/>
      <material name="black">
        <color rgba="0.0 0.0 0.0 2.0"/>
      </material>
    </visual>
  </link>

  <!-- Left side connector -->
  <joint name="body_link_BD2CL(0)" type="fixed">
    <parent link="body_link_body(0)"/>
    <child link="CL(0)"/>
    <origin xyz="-0.15 -0.05 0" rpy="0 0 -1.5708"/>
  </joint>
  <link name="CL(0)">
    <!-- Only visual, No collision -->
    <visual>
      <geometry>
        <cylinder length="0.01" radius="0.03"/>
      </geometry>
      <origin xyz="0 0 0" rpy="0 1.5708 0"/>
      <material name="black">
        <color rgba="0.0 0.0 0.0 2.0"/>
      </material>
    </visual>
  </link>

  <!-- Rear connector -->
  <link name="CR(3)">
    <!-- Only visual, No collision -->
    <visual>
      <geometry>
        <cylinder length="0.01" radius="0.03"/>
      </geometry>
      <origin xyz="0 0 0" rpy="0 1.5708 0"/>
      <material name="black">
        <color rgba="0.0 0.0 0.0 2.0"/>
      </material>
    </visual>
  </link>

  <!-- body -->
  <joint name="CR2BD(3)" type="fixed">
    <parent link="CR(3)"/>
    <child link="body_link_body(3)"/>
    <origin xyz="0 0 0" rpy="0 0 0"/>
  </joint>
  <link name="body_link_body(3)">
    <visual>
      <geometry>
        <cylinder length="0.30" radius="0.05"/>
      </geometry>
      <origin xyz="-0.15 0 0" rpy="0 1.5708 0"/>
      <material name="body_link_color">
        <color rgba="0.5 0.5 1.0 2.0"/>
      </material>
    </visual>
  </link>

  <!-- Front connector -->
  <joint name="body_link_BD2CF(3)" type="fixed">
    <parent link="body_link_body(3)"/>
    <child link="CF(3)"/>
    <origin xyz="-0.30 0 0" rpy="0 0 3.14159"/>
  </joint>
  <link name="CF(3)">
    <!-- Only visual, No collision -->
    <visual>
      <geometry>
        <cylinder length="0.01" radius="0.03"/>
      </geometry>
      <origin xyz="0 0 0" rpy="0 1.5708 0"/>
      <material name="black">
        <color rgba="0.0 0.0 0.0 2.0"/>
      </material>
    </visual>
  </link>

  <!-- Right side connector -->
  <joint name="body_link_BD2CRi(3)" type="fixed">
    <parent link="body_link_body(3)"/>
    <child link="CRi(3)"/>
    <origin xyz="-0.15 0.05 0" rpy="0 0 1.5708"/>
  </joint>
  <link name="CRi(3)">
    <!-- Only visual, No collision -->
    <visual>
      <geometry>
        <cylinder length="0.01" radius="0.03"/>
      </geometry>
      <origin xyz="0 0 0" rpy="0 1.5708 0"/>
      <material name="black">
        <color rgba="0.0 0.0 0.0 2.0"/>
      </material>
    </visual>
  </link>

  <!-- Left side connector -->
  <joint name="body_link_BD2CL(3)" type="fixed">
    <parent link="body_link_body(3)"/>
    <child link="CL(3)"/>
    <origin xyz="-0.15 -0.05 0" rpy="0 0 -1.5708"/>
  </joint>
  <link name="CL(3)">
    <!-- Only visual, No collision -->
    <visual>
      <geometry>
        <cylinder length="0.01" radius="0.03"/>
      </geometry>
      <origin xyz="0 0 0" rpy="0 1.5708 0"/>
      <material name="black">
        <color rgba="0.0 0.0 0.0 2.0"/>
      </material>
    </visual>
  </link>

  <!-- Rear body_rigid_joint -->
  <link name="CR(7)">
    <!-- Only visual, No collision -->
    <visual>
      <geometry>
        <cylinder length="0.01" radius="0.03"/>
      </geometry>
      <origin xyz="0 0 0" rpy="0 1.5708 0"/>
      <material name="black">
        <color rgba="0.0 0.0 0.0 2.0"/>
      </material>
    </visual>
  </link>

  <!-- body -->
  <joint name="body_rigid_joint(7)" type="fixed">
    <parent link="CR(7)"/>
    <child link="body_rigid_joint_cap(7)"/>
    <origin xyz="0 0 0" rpy="0 0 0"/>
  </joint>
  <link name="body_rigid_joint_cap(7)">
    <visual>
      <geometry>
        <box size="0.1 0.1 0.1"/>
      </geometry>
      <origin xyz="-0.05 0 0" rpy="0 0 0"/>
      <material name="body_rigid_joint_color">
        <color rgba="2.0 1.0 0.5 2.0"/>
      </material>
    </visual>
  </link>

  <!-- Front body_rigid_joint -->
  <joint name="body_rigid_joint_link_BD2CF(7)" type="fixed">
    <parent link="body_rigid_joint_cap(7)"/>
    <child link="CF(7)"/>
    <origin xyz="-0.1 0 0" rpy="0 0 3.14159"/>
  </joint>
  <link name="CF(7)">
    <!-- Only visual, No collision -->
    <visual>
      <geometry>
        <cylinder length="0.01" radius="0.03"/>
      </geometry>
      <origin xyz="0 0 0" rpy="0 1.5708 0"/>
      <material name="black">
        <color rgba="0.0 0.0 0.0 2.0"/>
      </material>
    </visual>
  </link>

  <!-- Rear connector -->
  <link name="CR(10)">
    <!-- Only visual, No collision -->
    <visual>
      <geometry>
        <cylinder length="0.01" radius="0.03"/>
      </geometry>
      <origin xyz="0 0 0" rpy="0 1.5708 0"/>
      <material name="black">
        <color rgba="0.0 0.0 0.0 2.0"/>
      </material>
    </visual>
  </link>

  <!-- body -->
  <joint name="CR2BD(10)" type="fixed">
    <parent link="CR(10)"/>
    <child link="limb_link15cm_body(10)"/>
    <origin xyz="0 0 0" rpy="0 0 0"/>
  </joint>
  <link name="limb_link15cm_body(10)">
    <visual>
      <geometry>
        <cylinder length="0.15" radius="0.03"/>
      </geometry>
      <origin xyz="-0.075 0 0" rpy="0 1.5708 0"/>
      <material name="limb_link_15cm_color">
        <color rgba="0.0 0.5 1.0 2.0"/>
      </material>
    </visual>
  </link>

  <!-- Front connector -->
  <joint name="limb_link15cm_BD2CF(10)" type="fixed">
    <parent link="limb_link15cm_body(10)"/>
    <child link="CF(10)"/>
    <origin xyz="-0.15 0 0" rpy="0 0 3.14159"/>
  </joint>
  <link name="CF(10)">
    <!-- Only visual, No collision -->
    <visual>
      <geometry>
        <cylinder length="0.01" radius="0.03"/>
      </geometry>
      <origin xyz="0 0 0" rpy="0 1.5708 0"/>
      <material name="black">
        <color rgba="0.0 0.0 0.0 2.0"/>
      </material>
    </visual>
  </link>

  <!-- Rear connector -->
  <link name="CR(13)">
    <!-- Only visual, No collision -->
    <visual>
      <geometry>
        <cylinder length="0.01" radius="0.03"/>
      </geometry>
      <origin xyz="0 0 0" rpy="0 1.5708 0"/>
      <material name="black">
        <color rgba="0.0 0.0 0.0 2.0"/>
      </material>
    </visual>
  </link>

  <!-- body -->
  <joint name="CR2BD(13)" type="fixed">
    <parent link="CR(13)"/>
    <child link="limb_link15cm_body(13)"/>
    <origin xyz="0 0 0" rpy="0 0 0"/>
  </joint>
  <link name="limb_link15cm_body(13)">
    <visual>
      <geometry>
        <cylinder length="0.15" radius="0.03"/>
      </geometry>
      <origin xyz="-0.075 0 0" rpy="0 1.5708 0"/>
      <material name="limb_link_15cm_color">
        <color rgba="0.0 0.5 1.0 2.0"/>
      </material>
    </visual>
  </link>

  <!-- Front connector -->
  <joint name="limb_link15cm_BD2CF(13)" type="fixed">
    <parent link="limb_link15cm_body(13)"/>
    <child link="CF(13)"/>
    <origin xyz="-0.15 0 0" rpy="0 0 3.14159"/>
  </joint>
  <link name="CF(13)">
    <!-- Only visual, No collision -->
    <visual>
      <geometry>
        <cylinder length="0.01" radius="0.03"/>
      </geometry>
      <origin xyz="0 0 0" rpy="0 1.5708 0"/>
      <material name="black">
        <color rgba="0.0 0.0 0.0 2.0"/>
      </material>
    </visual>
  </link>

  <!-- Rear connector -->
  <link name="CR(16)">
    <!-- Only visual, No collision -->
    <visual>
      <geometry>
        <cylinder length="0.01" radius="0.03"/>
      </geometry>
      <origin xyz="0 0 0" rpy="0 1.5708 0"/>
      <material name="black">
        <color rgba="0.0 0.0 0.0 2.0"/>
      </material>
    </visual>
  </link>

  <!-- body -->
  <joint name="CR2BD(16)" type="fixed">
    <parent link="CR(16)"/>
    <child link="limb_link15cm_body(16)"/>
    <origin xyz="0 0 0" rpy="0 0 0"/>
  </joint>
  <link name="limb_link15cm_body(16)">
    <visual>
      <geometry>
        <cylinder length="0.15" radius="0.03"/>
      </geometry>
      <origin xyz="-0.075 0 0" rpy="0 1.5708 0"/>
      <material name="limb_link_15cm_color">
        <color rgba="0.0 0.5 1.0 2.0"/>
      </material>
    </visual>
  </link>

  <!-- Front connector -->
  <joint name="limb_link15cm_BD2CF(16)" type="fixed">
    <parent link="limb_link15cm_body(16)"/>
    <child link="CF(16)"/>
    <origin xyz="-0.15 0 0" rpy="0 0 3.14159"/>
  </joint>
  <link name="CF(16)">
    <!-- Only visual, No collision -->
    <visual>
      <geometry>
        <cylinder length="0.01" radius="0.03"/>
      </geometry>
      <origin xyz="0 0 0" rpy="0 1.5708 0"/>
      <material name="black">
        <color rgba="0.0 0.0 0.0 2.0"/>
      </material>
    </visual>
  </link>

  <!-- Rear connector -->
  <link name="CR(19)">
    <!-- Only visual, No collision -->
    <visual>
      <geometry>
        <cylinder length="0.01" radius="0.03"/>
      </geometry>
      <origin xyz="0 0 0" rpy="0 1.5708 0"/>
      <material name="black">
        <color rgba="0.0 0.0 0.0 2.0"/>
      </material>
    </visual>
  </link>

  <!-- body -->
  <joint name="CR2BD(19)" type="fixed">
    <parent link="CR(19)"/>
    <child link="limb_link15cm_body(19)"/>
    <origin xyz="0 0 0" rpy="0 0 0"/>
  </joint>
  <link name="limb_link15cm_body(19)">
    <visual>
      <geometry>
        <cylinder length="0.15" radius="0.03"/>
      </geometry>
      <origin xyz="-0.075 0 0" rpy="0 1.5708 0"/>
      <material name="limb_link_15cm_color">
        <color rgba="0.0 0.5 1.0 2.0"/>
      </material>
    </visual>
  </link>

  <!-- Front connector -->
  <joint name="limb_link15cm_BD2CF(19)" type="fixed">
    <parent link="limb_link15cm_body(19)"/>
    <child link="CF(19)"/>
    <origin xyz="-0.15 0 0" rpy="0 0 3.14159"/>
  </joint>
  <link name="CF(19)">
    <!-- Only visual, No collision -->
    <visual>
      <geometry>
        <cylinder length="0.01" radius="0.03"/>
      </geometry>
      <origin xyz="0 0 0" rpy="0 1.5708 0"/>
      <material name="black">
        <color rgba="0.0 0.0 0.0 2.0"/>
      </material>
    </visual>
  </link>

  <!-- Rear limb_rigid_joint -->
  <link name="CR(22)">
    <!-- Only visual, No collision -->
    <visual>
      <geometry>
        <cylinder length="0.01" radius="0.03"/>
      </geometry>
      <origin xyz="0 0 0" rpy="0 1.5708 0"/>
      <material name="black">
        <color rgba="0.0 0.0 0.0 2.0"/>
      </material>
    </visual>
  </link>

  <!-- limb -->
  <joint name="CR2BD(22)" type="fixed">
    <parent link="CR(22)"/>
    <child link="limb_rigid_joint_cap(22)"/>
    <origin xyz="0 0 0" rpy="0 0 0"/>
  </joint>
  <link name="limb_rigid_joint_cap(22)">
    <visual>
      <geometry>
        <box size="0.06 0.06 0.06"/>
      </geometry>
      <origin xyz="-0.03 0 0" rpy="0 0 0"/>
      <material name="limb_rigid_joint_color">
        <color rgba="2.0 1.0 0.5 2.0"/>
      </material>
    </visual>
  </link>

  <!-- Front limb_rigid_joint -->
  <joint name="limb_rigid_joint_link_BD2CF(22)" type="fixed">
    <parent link="limb_rigid_joint_cap(22)"/>
    <child link="CF(22)"/>
    <origin xyz="-0.06 0 0" rpy="0 0 3.14159"/>
  </joint>
  <link name="CF(22)">
    <!-- Only visual, No collision -->
    <visual>
      <geometry>
        <cylinder length="0.01" radius="0.03"/>
      </geometry>
      <origin xyz="0 0 0" rpy="0 1.5708 0"/>
      <material name="black">
        <color rgba="0.0 0.0 0.0 2.0"/>
      </material>
    </visual>
  </link>

  <!-- Rear limb_roll_joint -->
  <link name="CR(25)">
    <!-- Only visual, No collision -->
    <visual>
      <geometry>
        <cylinder length="0.01" radius="0.03"/>
      </geometry>
      <origin xyz="0 0 0" rpy="0 1.5708 0"/>
      <material name="black">
        <color rgba="0.0 0.0 0.0 2.0"/>
      </material>
    </visual>
  </link>

  <!-- limb -->
  <joint name="limb_roll_joint(25)" type="revolute">
    <parent link="CR(25)"/>
    <child link="limb_roll_joint_cap(25)"/>
    <origin xyz="-0.03 0 0" rpy="0 0 0"/>
    <axis xyz="0 0 1"/>
    <limit lower="-1.5708" upper="1.5708" effort="0" velocity="0"/>
  </joint>
  <link name="limb_roll_joint_cap(25)">
    <visual>
      <geometry>
        <cylinder length="0.06" radius="0.03"/>
      </geometry>
      <origin xyz="0 0 0" rpy="0 0 0"/>
      <material name="limb_roll_joint_color">
        <color rgba="0.0 1.0 0.5 2.0"/>
      </material>
    </visual>
  </link>

  <!-- Front limb_roll_joint -->
  <joint name="limb_roll_joint_link_BD2CF(25)" type="fixed">
    <parent link="limb_roll_joint_cap(25)"/>
    <child link="CF(25)"/>
    <origin xyz="-0.03 0 0" rpy="0 0 3.14159"/>
  </joint>
  <link name="CF(25)">
    <!-- Only visual, No collision -->
    <visual>
      <geometry>
        <cylinder length="0.01" radius="0.03"/>
      </geometry>
      <origin xyz="0 0 0" rpy="0 1.5708 0"/>
      <material name="black">
        <color rgba="0.0 0.0 0.0 2.0"/>
      </material>
    </visual>
  </link>

  <!-- Rear limb_knee_joint -->
  <link name="CR(45)">
    <!-- Only visual, No collision -->
    <visual>
      <geometry>
        <cylinder length="0.01" radius="0.03"/>
      </geometry>
      <origin xyz="0 0 0" rpy="0 1.5708 0"/>
      <material name="black">
        <color rgba="0.0 0.0 0.0 2.0"/>
      </material>
    </visual>
  </link>

  <!-- limb -->
  <joint name="limb_knee_joint_i(45)" type="revolute">
    <parent link="CR(45)"/>
    <child link="limb_knee_joint_cap(45)"/>
    <origin xyz="-0.03 0 0" rpy="0 0 0"/>
    <axis xyz="1 0 0"/>
    <limit lower="-1.5708" upper="1.5708" effort="0" velocity="0"/>
  </joint>
  <link name="limb_knee_joint_cap(45)">
    <visual>
      <geometry>
        <cylinder length="0.06" radius="0.03"/>
      </geometry>
      <origin xyz="0 0 0" rpy="0 0 0"/>
      <material name="limb_knee_joint_color">
        <color rgba="0.0 1.0 0.5 2.0"/>
      </material>
    </visual>
  </link>

  <!-- middle -->
  <joint name="limb_knee_joint_r(45)" type="revolute">
    <parent link="limb_knee_joint_cap(45)"/>
    <child link="limb_knee_joint_invisible_link(45)"/>
    <origin xyz="0 0 0" rpy="0 0 0"/>
    <axis xyz="0 0 1"/>
    <limit lower="-1.5708" upper="1.5708" effort="0" velocity="0"/>
  </joint>
  <link name="limb_knee_joint_invisible_link(45)">
  </link>

  <!-- Front limb_knee_joint -->
  <joint name="limb_knee_joint_invisible(45)" type="fixed">
    <parent link="limb_knee_joint_invisible_link(45)"/>
    <child link="CF(45)"/>
    <origin xyz="-0.03 0 0" rpy="0 0 3.14159"/>
  </joint>
  <link name="CF(45)">
    <!-- Only visual, No collision -->
    <visual>
      <geometry>
        <cylinder length="0.01" radius="0.03"/>
      </geometry>
      <origin xyz="0.0 0 0" rpy="0 1.5708 0"/>
      <material name="black">
        <color rgba="0.0 0.0 0.0 2.0"/>
      </material>
    </visual>
  </link>

  <!-- Rear limb_knee_joint -->
  <link name="CR(48)">
    <!-- Only visual, No collision -->
    <visual>
      <geometry>
        <cylinder length="0.01" radius="0.03"/>
      </geometry>
      <origin xyz="0 0 0" rpy="0 1.5708 0"/>
      <material name="black">
        <color rgba="0.0 0.0 0.0 2.0"/>
      </material>
    </visual>
  </link>

  <!-- limb -->
  <joint name="limb_knee_joint_i(48)" type="revolute">
    <parent link="CR(48)"/>
    <child link="limb_knee_joint_cap(48)"/>
    <origin xyz="-0.03 0 0" rpy="0 0 0"/>
    <axis xyz="1 0 0"/>
    <limit lower="-1.5708" upper="1.5708" effort="0" velocity="0"/>
  </joint>
  <link name="limb_knee_joint_cap(48)">
    <visual>
      <geometry>
        <cylinder length="0.06" radius="0.03"/>
      </geometry>
      <origin xyz="0 0 0" rpy="0 0 0"/>
      <material name="limb_knee_joint_color">
        <color rgba="0.0 1.0 0.5 2.0"/>
      </material>
    </visual>
  </link>

  <!-- middle -->
  <joint name="limb_knee_joint_r(48)" type="revolute">
    <parent link="limb_knee_joint_cap(48)"/>
    <child link="limb_knee_joint_invisible_link(48)"/>
    <origin xyz="0 0 0" rpy="0 0 0"/>
    <axis xyz="0 0 1"/>
    <limit lower="-1.5708" upper="1.5708" effort="0" velocity="0"/>
  </joint>
  <link name="limb_knee_joint_invisible_link(48)">
  </link>

  <!-- Front limb_knee_joint -->
  <joint name="limb_knee_joint_invisible(48)" type="fixed">
    <parent link="limb_knee_joint_invisible_link(48)"/>
    <child link="CF(48)"/>
    <origin xyz="-0.03 0 0" rpy="0 0 3.14159"/>
  </joint>
  <link name="CF(48)">
    <!-- Only visual, No collision -->
    <visual>
      <geometry>
        <cylinder length="0.01" radius="0.03"/>
      </geometry>
      <origin xyz="0.0 0 0" rpy="0 1.5708 0"/>
      <material name="black">
        <color rgba="0.0 0.0 0.0 2.0"/>
      </material>
    </visual>
  </link>

  <!-- Rear connector -->
  <link name="CR(51)">
    <!-- Only visual, No collision -->
    <visual>
      <geometry>
        <cylinder length="0.01" radius="0.03"/>
      </geometry>
      <origin xyz="0 0 0" rpy="0 1.5708 0"/>
      <material name="black">
        <color rgba="0.0 0.0 0.0 2.0"/>
      </material>
    </visual>
  </link>

  <!-- Front connector -->
  <joint name="CR2CF(51)" type="fixed">
    <parent link="CR(51)"/>
    <child link="CF(51)"/>
    <origin xyz="-0.01 0 0" rpy="0 0 3.14159"/>
  </joint>
  <link name="CF(51)">
    <!-- Only visual, No collision -->
    <visual>
      <geometry>
        <cylinder length="0.01" radius="0.03"/>
      </geometry>
      <origin xyz="0 0 0" rpy="0 1.5708 0"/>
      <material name="black">
        <color rgba="0.0 0.0 0.0 2.0"/>
      </material>
    </visual>
  </link>

  <!-- Rear connector -->
  <link name="CR(54)">
    <!-- Only visual, No collision -->
    <visual>
      <geometry>
        <cylinder length="0.01" radius="0.03"/>
      </geometry>
      <origin xyz="0 0 0" rpy="0 1.5708 0"/>
      <material name="black">
        <color rgba="0.0 0.0 0.0 2.0"/>
      </material>
    </visual>
  </link>

  <!-- body -->
  <joint name="CR2BD(54)" type="fixed">
    <parent link="CR(54)"/>
    <child link="mount_link_body(54)"/>
    <origin xyz="0 0 0" rpy="0 0 0"/>
  </joint>
  <link name="mount_link_body(54)">
    <visual>
      <geometry>
        <cylinder length="0.10" radius="0.03"/>
      </geometry>
      <origin xyz="-0.05 0 0" rpy="0 1.5708 0"/>
      <material name="mount_link_color">
        <color rgba="0.0 0.5 1.0 2.0"/>
      </material>
    </visual>
  </link>

  <!-- Front connector -->
  <joint name="mount_link_BD2CF(54)" type="fixed">
    <parent link="mount_link_body(54)"/>
    <child link="CF(54)"/>
    <origin xyz="-0.1 0 0" rpy="0 0 3.14159"/>
  </joint>
  <link name="CF(54)">
    <!-- Only visual, No collision -->
    <visual>
      <geometry>
        <cylinder length="0.01" radius="0.03"/>
      </geometry>
      <origin xyz="0 0 0" rpy="0 1.5708 0"/>
      <material name="black">
        <color rgba="0.0 0.0 0.0 2.0"/>
      </material>
    </visual>
  </link>

  <!-- Rear connector -->
  <link name="CR(57)">
    <!-- Only visual, No collision -->
    <visual>
      <geometry>
        <cylinder length="0.01" radius="0.03"/>
      </geometry>
      <origin xyz="0 0 0" rpy="0 1.5708 0"/>
      <material name="black">
        <color rgba="0.0 0.0 0.0 2.0"/>
      </material>
    </visual>
  </link>

  <!-- Front connector -->
  <joint name="CR2CF(57)" type="fixed">
    <parent link="CR(57)"/>
    <child link="CF(57)"/>
    <origin xyz="-0.01 0 0" rpy="0 0 3.14159"/>
  </joint>
  <link name="CF(57)">
    <!-- Only visual, No collision -->
    <visual>
      <geometry>
        <cylinder length="0.01" radius="0.03"/>
      </geometry>
      <origin xyz="0 0 0" rpy="0 1.5708 0"/>
      <material name="black">
        <color rgba="0.0 0.0 0.0 2.0"/>
      </material>
    </visual>
  </link>

  <!-- Rear connector -->
  <link name="CR(60)">
    <!-- Only visual, No collision -->
    <visual>
      <geometry>
        <cylinder length="0.01" radius="0.03"/>
      </geometry>
      <origin xyz="0 0 0" rpy="0 1.5708 0"/>
      <material name="black">
        <color rgba="0.0 0.0 0.0 2.0"/>
      </material>
    </visual>
  </link>

  <!-- body -->
  <joint name="CR2BD(60)" type="fixed">
    <parent link="CR(60)"/>
    <child link="mount_link_body(60)"/>
    <origin xyz="0 0 0" rpy="0 0 0"/>
  </joint>
  <link name="mount_link_body(60)">
    <visual>
      <geometry>
        <cylinder length="0.10" radius="0.03"/>
      </geometry>
      <origin xyz="-0.05 0 0" rpy="0 1.5708 0"/>
      <material name="mount_link_color">
        <color rgba="0.0 0.5 1.0 2.0"/>
      </material>
    </visual>
  </link>

  <!-- Front connector -->
  <joint name="mount_link_BD2CF(60)" type="fixed">
    <parent link="mount_link_body(60)"/>
    <child link="CF(60)"/>
    <origin xyz="-0.1 0 0" rpy="0 0 3.14159"/>
  </joint>
  <link name="CF(60)">
    <!-- Only visual, No collision -->
    <visual>
      <geometry>
        <cylinder length="0.01" radius="0.03"/>
      </geometry>
      <origin xyz="0 0 0" rpy="0 1.5708 0"/>
      <material name="black">
        <color rgba="0.0 0.0 0.0 2.0"/>
      </material>
    </visual>
  </link>

  <!-- Rear wheel -->
  <link name="CR(62)">
    <!-- Only visual, No collision -->
    <visual>
      <geometry>
        <cylinder length="0.01" radius="0.03"/>
      </geometry>
      <origin xyz="0 0 0" rpy="0 1.5708 0"/>
      <material name="black">
        <color rgba="0.0 0.0 0.0 2.0"/>
      </material>
    </visual>
  </link>

  <!-- limb -->
  <joint name="wheel(62)" type="continuous">
    <parent link="CR(62)"/>
    <child link="wheel_tyre(62)"/>
    <origin xyz="-0.03 0 0" rpy="0 0 0"/>
    <axis xyz="1 0 0"/>
  </joint>
  <link name="wheel_tyre(62)">
    <visual>
      <geometry>
        <cylinder length="0.06" radius="0.1"/>
      </geometry>
      <origin xyz="0 0 0" rpy="0 1.5708 0"/>
      <material name="wheel_color">
        <color rgba="0.0 0.5 1.0 2.0"/>
      </material>
    </visual>
  </link>

  <!-- Rear empty_edge -->
  <link name="CR(64)">
    <!-- Only visual, No collision -->
    <visual>
      <geometry>
        <cylinder length="0.01" radius="0.03"/>
      </geometry>
      <origin xyz="0 0 0" rpy="0 1.5708 0"/>
      <material name="black">
        <color rgba="0.0 0.0 0.0 2.0"/>
      </material>
    </visual>
  </link>

  <!-- limb -->
  <joint name="empty_edge(64)" type="fixed">
    <parent link="CR(64)"/>
    <child link="empty_edge_ball(64)"/>
    <origin xyz="0 0 0" rpy="0 0 0"/>
  </joint>
  <link name="empty_edge_ball(64)">
    <visual>
      <geometry>
        <sphere radius="0.03"/>
      </geometry>
      <origin xyz="0 0 0" rpy="0 1.5708 0"/>
      <material name="empty_edge_color">
        <color rgba="0.0 0.5 1.0 2.0"/>
      </material>
    </visual>
  </link>
  <joint name ="CF(0)ToCR(51)" type="fixed">
    <parent link="CF(0)"/>
    <child link="CR(51)"/>
    <origin xyz="0 0 0" rpy="0 0 3.14159265359"/>
  </joint>
  <joint name ="CF(3)ToCR(7)" type="fixed">
    <parent link="CF(3)"/>
    <child link="CR(7)"/>
    <origin xyz="0 0 0" rpy="0 0 3.14159265359"/>
  </joint>
  <joint name ="CF(7)ToCR(0)" type="fixed">
    <parent link="CF(7)"/>
    <child link="CR(0)"/>
    <origin xyz="0 0 0" rpy="0 0 3.14159265359"/>
  </joint>
  <joint name ="CF(10)ToCR(62)" type="fixed">
    <parent link="CF(10)"/>
    <child link="CR(62)"/>
    <origin xyz="0 0 0" rpy="0 0 3.14159265359"/>
  </joint>
  <joint name ="CF(13)ToCR(22)" type="fixed">
    <parent link="CF(13)"/>
    <child link="CR(22)"/>
    <origin xyz="0 0 0" rpy="0 0 3.14159265359"/>
  </joint>
  <joint name ="CF(16)ToCR(48)" type="fixed">
    <parent link="CF(16)"/>
    <child link="CR(48)"/>
    <origin xyz="0 0 0" rpy="0 0 3.14159265359"/>
  </joint>
  <joint name ="CF(19)ToCR(64)" type="fixed">
    <parent link="CF(19)"/>
    <child link="CR(64)"/>
    <origin xyz="0 0 0" rpy="0 0 3.14159265359"/>
  </joint>
  <joint name ="CF(22)ToCR(19)" type="fixed">
    <parent link="CF(22)"/>
    <child link="CR(19)"/>
    <origin xyz="0 0 0" rpy="0 0 3.14159265359"/>
  </joint>
  <joint name ="CF(25)ToCR(10)" type="fixed">
    <parent link="CF(25)"/>
    <child link="CR(10)"/>
    <origin xyz="0 0 0" rpy="0 0 3.14159265359"/>
  </joint>
  <joint name ="CF(45)ToCR(16)" type="fixed">
    <parent link="CF(45)"/>
    <child link="CR(16)"/>
    <origin xyz="0 0 0" rpy="0 0 3.14159265359"/>
  </joint>
  <joint name ="CF(48)ToCR(13)" type="fixed">
    <parent link="CF(48)"/>
    <child link="CR(13)"/>
    <origin xyz="0 0 0" rpy="0 0 3.14159265359"/>
  </joint>
  <joint name ="CF(51)ToCR(54)" type="fixed">
    <parent link="CF(51)"/>
    <child link="CR(54)"/>
    <origin xyz="0 0 0" rpy="0 0 3.14159265359"/>
  </joint>
  <joint name ="CF(54)ToCR(25)" type="fixed">
    <parent link="CF(54)"/>
    <child link="CR(25)"/>
    <origin xyz="0 0 0" rpy="0 0 3.14159265359"/>
  </joint>
  <joint name ="CF(57)ToCR(60)" type="fixed">
    <parent link="CF(57)"/>
    <child link="CR(60)"/>
    <origin xyz="0 0 0" rpy="0 0 3.14159265359"/>
  </joint>
  <joint name ="CR(57)ToCR(3)" type="fixed">
    <parent link="CR(57)"/>
    <child link="CR(3)"/>
    <origin xyz="0 0 0" rpy="0 0 3.14159265359"/>
  </joint>
  <joint name ="CF(60)ToCR(45)" type="fixed">
    <parent link="CF(60)"/>
    <child link="CR(45)"/>
    <origin xyz="0 0 0" rpy="0 0 3.14159265359"/>
  </joint>
</robot>