<?xml version="1.0"?>

<robot name="wheel_link">
  <!-- FOR CONVENTIONAL URDF DESCRIPTION -->
  <link name="base_link"/>
  <joint name="limb_joint" type="fixed">
    <parent link="base_link"/>
    <child link="CR(id)"/>
  </joint>

  <!-- Module structure description -->
  <!-- Each link and joint must have "(id)" in the name-->
  <!-- PYTHON_READ_START -->

  <!-- Rear wheel -->
  <link name="CR(id)">
    <!-- Only visual, No collision -->
    <visual>
      <geometry>
        <cylinder length="0.01" radius="0.03"/>
      </geometry>
      <origin xyz="0 0 0" rpy="0 1.5708 0"/>
      <material name="black">
        <color rgba="0.0 0.0 0.0 2.0"/>
      </material>
    </visual>
  </link>

  <!-- limb -->
  <joint name="wheel(id)" type="continuous">
    <parent link="CR(id)"/>
    <child link="wheel_tyre(id)"/>
    <origin xyz="-0.03 0 0" rpy="0 0 0"/>
    <axis xyz="1 0 0"/>
  </joint>
  <link name="wheel_tyre(id)">
    <visual>
      <geometry>
        <cylinder length="0.06" radius="0.1"/>
      </geometry> 
      <origin xyz="0 0 0" rpy="0 1.5708 0"/>
      <material name="wheel_color">
        <color rgba="0.0 0.5 1.0 2.0"/>
      </material>
    </visual>
  </link>
  <!-- PYTHON_READ_END -->
  
</robot>
